<?xml version="1.0" ?>
<!-- =================================================================================== -->
<!-- |    This document was autogenerated by xacro from diff_drive_1.urdf.xacro        | -->
<!-- |    EDITING THIS FILE BY HAND IS NOT RECOMMENDED                                 | -->
<!-- =================================================================================== -->
<robot name="diff_drive">
  <!-- Robot Base -->
  <link name="base_link">
    <visual>
      <geometry>
        <box size="0.133 0.265 0.347"/>
      </geometry>
      <material name="Cyan">
        <color rgba="0 1.0 1.0 1.0"/>
      </material>
    </visual>
    <collision>
      <geometry>
        <box size="0.133 0.265 0.347"/>
      </geometry>
    </collision>
    <inertial>
      <origin rpy="1.5707963267948966 0 1.5707963267948966" xyz="0 0 0"/>
      <mass value="30"/>
      <inertia ixx="0.345245" ixy="0.0" ixz="0.0" iyy="0.21978500000000006" iyz="0.0" izz="0.476585"/>
    </inertial>
  </link>
  <!-- Robot Footprint -->
  <link name="base_footprint">
    <inertial>
      <origin rpy="1.5707963267948966 0 1.5707963267948966" xyz="0 0 0"/>
      <mass value="0"/>
      <inertia ixx="0.0" ixy="0.0" ixz="0.0" iyy="0.0" iyz="0.0" izz="0.0"/>
    </inertial>
  </link>
  <joint name="base_joint" type="fixed">
    <parent link="base_link"/>
    <child link="base_footprint"/>
    <origin rpy="0 0 0" xyz="0.0 0.0 -0.04735"/>
  </joint>
  <link name="drivewhl_l_link">
    <visual>
      <origin rpy="1.5707963267948966 0 0" xyz="0 0 0"/>
      <geometry>
        <cylinder length="0.02" radius="0.02735"/>
      </geometry>
      <material name="Gray">
        <color rgba="0.5 0.5 0.5 1.0"/>
      </material>
    </visual>
    <collision>
      <origin rpy="1.5707963267948966 0 0" xyz="0 0 0"/>
      <geometry>
        <cylinder length="0.02" radius="0.02735"/>
      </geometry>
    </collision>
    <inertial>
      <origin rpy="1.5707963267948966 0 0" xyz="0 0 0"/>
      <mass value="0.5"/>
      <inertia ixx="0.00011016947916666667" ixy="0" ixz="0" iyy="0.00011016947916666667" iyz="0" izz="0.00018700562499999999"/>
    </inertial>
  </link>
  <joint name="drivewhl_l_joint" type="continuous">
    <parent link="base_link"/>
    <child link="drivewhl_l_link"/>
    <origin rpy="0 0 0" xyz="-0.05 0.1575 -0.1535"/>
    <axis xyz="0 1 0"/>
  </joint>
  <link name="drivewhl_r_link">
    <visual>
      <origin rpy="1.5707963267948966 0 0" xyz="0 0 0"/>
      <geometry>
        <cylinder length="0.02" radius="0.02735"/>
      </geometry>
      <material name="Gray">
        <color rgba="0.5 0.5 0.5 1.0"/>
      </material>
    </visual>
    <collision>
      <origin rpy="1.5707963267948966 0 0" xyz="0 0 0"/>
      <geometry>
        <cylinder length="0.02" radius="0.02735"/>
      </geometry>
    </collision>
    <inertial>
      <origin rpy="1.5707963267948966 0 0" xyz="0 0 0"/>
      <mass value="0.5"/>
      <inertia ixx="0.00011016947916666667" ixy="0" ixz="0" iyy="0.00011016947916666667" iyz="0" izz="0.00018700562499999999"/>
    </inertial>
  </link>
  <joint name="drivewhl_r_joint" type="continuous">
    <parent link="base_link"/>
    <child link="drivewhl_r_link"/>
    <origin rpy="0 0 0" xyz="-0.05 -0.1575 -0.1535"/>
    <axis xyz="0 1 0"/>
  </joint>
  <link name="left_caster">
    <visual>
      <geometry>
        <sphere radius="0.007349999999999999"/>
      </geometry>
      <material name="Cyan">
        <color rgba="0 1.0 1.0 1.0"/>
      </material>
    </visual>
    <collision>
      <origin rpy="0 0 0" xyz="0 0 0"/>
      <geometry>
        <sphere radius="0.007349999999999999"/>
      </geometry>
      <surface>
        <friction>
          <mu>0</mu>
          <mu2>0</mu2>
        </friction>
      </surface>
    </collision>
    <inertial>
      <mass value="0.5"/>
      <inertia ixx="1.0804499999999998e-05" ixy="0.0" ixz="0.0" iyy="1.0804499999999998e-05" iyz="0.0" izz="1.0804499999999998e-05"/>
    </inertial>
  </link>
  <joint name="left_caster_joint" type="continuous">
    <parent link="base_link"/>
    <child link="left_caster"/>
    <origin rpy="0 0 0" xyz="0.05 -0.1125 -0.1735"/>
    <axis xyz="0 1 0"/>
  </joint>
  <link name="right_caster">
    <visual>
      <geometry>
        <sphere radius="0.007349999999999999"/>
      </geometry>
      <material name="Cyan">
        <color rgba="0 1.0 1.0 1.0"/>
      </material>
    </visual>
    <collision>
      <origin rpy="0 0 0" xyz="0 0 0"/>
      <geometry>
        <sphere radius="0.007349999999999999"/>
      </geometry>
      <surface>
        <friction>
          <mu>0</mu>
          <mu2>0</mu2>
        </friction>
      </surface>
    </collision>
    <inertial>
      <mass value="0.5"/>
      <inertia ixx="1.0804499999999998e-05" ixy="0.0" ixz="0.0" iyy="1.0804499999999998e-05" iyz="0.0" izz="1.0804499999999998e-05"/>
    </inertial>
  </link>
  <joint name="right_caster_joint" type="continuous">
    <parent link="base_link"/>
    <child link="right_caster"/>
    <origin rpy="0 0 0" xyz="0.05 0.1125 -0.1735"/>
    <axis xyz="0 1 0"/>
  </joint>
  <gazebo>
    <plugin filename="libgazebo_ros_diff_drive.so" name="diff_drive_contrl">
      <ros>
        <namespace/>
      </ros>
      <always_on>true</always_on>
      <updateRate>100</updateRate>
      <commandTopic>cmd_vel</commandTopic>
      <publishTf>true</publishTf>
      <!-- about odometry parameter-->
      <publishWheelTF>false</publishWheelTF>
      <!-- <publish_wheel_joint_state>true</publish_wheel_joint_state> -->
      <publishWheelJointState>true</publishWheelJointState>
      <!-- <odometry_topic>odom</odometry_topic> -->
      <odometryTopic>odom</odometryTopic>
      <!-- wheels -->
      <!-- <left_joint>drivewhl_l_joint</left_joint> -->
      <!-- <right_joint>drivewhl_r_joint</right_joint> -->
      <leftJoint>drivewhl_l_joint</leftJoint>
      <rightJoint>drivewhl_r_joint</rightJoint>
      <!-- kinematics -->
      <!-- <wheel_separation>0.4</wheel_separation> -->
      <!-- <wheel_diameter>0.2</wheel_diameter> -->
      <wheelSeparation>0.4</wheelSeparation>
      <wheelDiameter>0.2</wheelDiameter>
      <!-- limits -->
      <!-- <max_wheel_torque>50</max_wheel_torque> -->
      <!-- <max_wheel_acceleration>3.0</max_wheel_acceleration> -->
      <wheelAcceleration>3</wheelAcceleration>
      <wheelTorque>50</wheelTorque>
      <!-- output -->
      <publish_odom>true</publish_odom>
      <!-- <publish_odom_tf>true</publish_odom_tf> -->
      <publishOdomTF>false</publishOdomTF>
      <!-- <publish_wheel_tf>true</publish_wheel_tf> -->
      <publishWheelTF>false</publishWheelTF>
      <!-- <odometry_frame>odom</odometry_frame> -->
      <odometryFrame>robot/odom</odometryFrame>
      <!-- <robot_base_frame>base_link</robot_base_frame> -->
      <robotBaseFrame>robot/base_footprint</robotBaseFrame>
      <gaussianNoise>0.1</gaussianNoise>
    </plugin>
    <!-- <plugin name='gazebo_ros_control' filename='libgazebo_ros_control.so'>
      <robotNamespace></robotNamespace>
      
    </plugin> -->
  </gazebo>
  <!-- setting up imu -->
  <link name="imu_link">
    <visual>
      <geometry>
        <box size="0.1 0.1 0.1"/>
      </geometry>
    </visual>
    <collision>
      <geometry>
        <box size="0.1 0.1 0.1"/>
      </geometry>
    </collision>
    <inertial>
      <origin rpy="1.5707963267948966 0 1.5707963267948966" xyz="0 0 0"/>
      <mass value="0.1"/>
      <inertia ixx="0.0001666666666666667" ixy="0.0" ixz="0.0" iyy="0.0001666666666666667" iyz="0.0" izz="0.0001666666666666667"/>
    </inertial>
  </link>
  <joint name="imu_joint" type="fixed">
    <parent link="base_link"/>
    <child link="imu_link"/>
    <origin xyz="0 0 0.01"/>
  </joint>
  <gazebo reference="imu_link">
    <sensor name="imu1" type="imu">
      <plugin filename="libgazebo_ros_imu_sensor.so" name="imu_plugin">
        <topicName>imu</topicName>
        <bodyName>imu_link</bodyName>
        <updateRateHZ>10.0</updateRateHZ>
        <gaussianNoise>0.0</gaussianNoise>
        <xyzOffset>0 0 0</xyzOffset>
        <rpyOffset>0 0 0</rpyOffset>
        <frameName>robot/imu_link</frameName>
        <initialOrientationAsReference>false</initialOrientationAsReference>
      </plugin>
      <always_on>true</always_on>
      <update_rate>100</update_rate>
      <visualize>true</visualize>
    </sensor>
  </gazebo>
  <!-- setting up LiDAR -->
  <link name="lidar_link">
    <visual>
      <geometry>
        <cylinder length="0.09" radius="0.0508"/>
      </geometry>
    </visual>
    <collision>
      <geometry>
        <cylinder length="0.09" radius="0.0508"/>
      </geometry>
    </collision>
    <inertial>
      <origin rpy="1.5707963267948966 0 0" xyz="0 0 0"/>
      <mass value="0.114"/>
      <inertia ixx="0.00015049823999999998" ixy="0" ixz="0" iyy="0.00015049823999999998" iyz="0" izz="0.00014709648"/>
    </inertial>
  </link>
  <joint name="lidar_joint" type="fixed">
    <parent link="base_link"/>
    <child link="lidar_link"/>
    <origin rpy="0 0 0" xyz="0.0 0.0 0.21849999999999997"/>
  </joint>
  <gazebo reference="lidar_link">
    <sensor name="lidar" type="ray">
      <ray>
        <scan>
          <horizontal>
            <samples>1800</samples>
            <resolution>1</resolution>
            <min_angle>0.000000</min_angle>
            <max_angle>6.280000</max_angle>
          </horizontal>
        </scan>
        <range>
          <min>0.280000</min>
          <max>3.7</max>
          <resolution>0.001000</resolution>
        </range>
        <noise>
          <type>gaussian</type>
          <mean>0.0</mean>
          <stddev>0.001</stddev>
        </noise>
      </ray>
      <plugin filename="libgazebo_ros_laser.so" name="scan">
        <!-- <ros><remapping>~/out:=scan</remapping></ros> -->
        <!-- <frame_name>lidar_link</frame_name> -->
        <!-- <output_type>sensor_msgs/LaserScan</output_type> -->
        <topicName>scan</topicName>
        <frameName>robot/base_scan</frameName>
      </plugin>
      <always_on>true</always_on>
      <update_rate>10</update_rate>
      <visualize>false</visualize>
    </sensor>
  </gazebo>
</robot>
